<?xml version="1.0" encoding="utf-8"?>
<!-- This URDF was automatically created by SolidWorks to URDF Exporter! Originally created by Stephen Brawner (brawner@gmail.com) 
     Commit Version: 1.5.1-0-g916b5db  Build Version: 1.5.7152.31018
     For more information, please see http://wiki.ros.org/sw_urdf_exporter -->
<robot
  name="05149">
  <link
    name="Body">
    <inertial>
      <origin
        xyz="0.108885138044438 0.0585567936495662 -0.142308649679038"
        rpy="0 0 0" />
      <mass
        value="5.32485366509136" />
      <inertia
        ixx="0.0219378727233069"
        ixy="-4.0175156182501E-06"
        ixz="-1.47975198134051E-06"
        iyy="0.023203020823872"
        iyz="-7.80337093935826E-06"
        izz="0.0149047739346839" />
    </inertial>
    <visual>
      <origin
        xyz="0 0 0"
        rpy="0 0 0" />
      <geometry>
        <mesh
          filename="package://05149/meshes/Body.STL" />
      </geometry>
      <material
        name="">
        <color
          rgba="0.752941176470588 0.752941176470588 0.752941176470588 1" />
      </material>
    </visual>
    <collision>
      <origin
        xyz="0 0 0"
        rpy="0 0 0" />
      <geometry>
        <mesh
          filename="package://05149/meshes/Body.STL" />
      </geometry>
    </collision>
  </link>
  <link
    name="LFS">
    <inertial>
      <origin
        xyz="0.066688 -0.025617 0.027258"
        rpy="0 0 0" />
      <mass
        value="0.26437" />
      <inertia
        ixx="3.2075E-05"
        ixy="-1.4412E-07"
        ixz="-6.3085E-08"
        iyy="6.227E-05"
        iyz="-2.0189E-07"
        izz="6.2852E-05" />
    </inertial>
    <visual>
      <origin
        xyz="0 0 0"
        rpy="0 0 0" />
      <geometry>
        <mesh
          filename="package://05149/meshes/LFS.STL" />
      </geometry>
      <material
        name="">
        <color
          rgba="0.75294 0.75294 0.75294 1" />
      </material>
    </visual>
    <collision>
      <origin
        xyz="0 0 0"
        rpy="0 0 0" />
      <geometry>
        <mesh
          filename="package://05149/meshes/LFS.STL" />
      </geometry>
    </collision>
  </link>
  <joint
    name="LFS"
    type="prismatic">
    <origin
      xyz="0.31516 0.026427 -0.050812"
      rpy="-1.8784 0 -3.1416" />
    <parent
      link="Body" />
    <child
      link="LFS" />
    <axis
      xyz="0 0.3028 -0.95305" />
    <limit
      lower="0"
      upper="0"
      effort="0"
      velocity="0" />
  </joint>
  <link
    name="LFW">
    <inertial>
      <origin
        xyz="-0.012316 0 3.4694E-18"
        rpy="0 0 0" />
      <mass
        value="0.19359" />
      <inertia
        ixx="0.00025308"
        ixy="-2.207E-23"
        ixz="8.8772E-22"
        iyy="0.00013682"
        iyz="0"
        izz="0.00013682" />
    </inertial>
    <visual>
      <origin
        xyz="0 0 0"
        rpy="0 0 0" />
      <geometry>
        <mesh
          filename="package://05149/meshes/LFW.STL" />
      </geometry>
      <material
        name="">
        <color
          rgba="1 1 1 1" />
      </material>
    </visual>
    <collision>
      <origin
        xyz="0 0 0"
        rpy="0 0 0" />
      <geometry>
        <mesh
          filename="package://05149/meshes/LFW.STL" />
      </geometry>
    </collision>
  </link>
  <joint
    name="LFW"
    type="continuous">
    <origin
      xyz="0.00041099 -0.047479 0.052309"
      rpy="-1.8707 0 3.1416" />
    <parent
      link="LFS" />
    <child
      link="LFW" />
    <axis
      xyz="1 0 0" />
    <limit
      effort="3.1"
      velocity="7" />
  </joint>
  <link
    name="RFS">
    <inertial>
      <origin
        xyz="0.072447 -0.031683 0.02534"
        rpy="0 0 0" />
      <mass
        value="0.26437" />
      <inertia
        ixx="3.2075E-05"
        ixy="1.4412E-07"
        ixz="6.3085E-08"
        iyy="6.227E-05"
        iyz="-2.0189E-07"
        izz="6.2852E-05" />
    </inertial>
    <visual>
      <origin
        xyz="0 0 0"
        rpy="0 0 0" />
      <geometry>
        <mesh
          filename="package://05149/meshes/RFS.STL" />
      </geometry>
      <material
        name="">
        <color
          rgba="0.75294 0.75294 0.75294 1" />
      </material>
    </visual>
    <collision>
      <origin
        xyz="0 0 0"
        rpy="0 0 0" />
      <geometry>
        <mesh
          filename="package://05149/meshes/RFS.STL" />
      </geometry>
    </collision>
  </link>
  <joint
    name="RFS"
    type="prismatic">
    <origin
      xyz="-0.10492 0.026427 -0.012128"
      rpy="1.2632 0 0" />
    <parent
      link="Body" />
    <child
      link="RFS" />
    <axis
      xyz="0 0.3028 -0.95305" />
    <limit
      lower="0"
      upper="0"
      effort="0"
      velocity="0" />
  </joint>
  <link
    name="RFW">
    <inertial>
      <origin
        xyz="-0.012316 -3.4694E-18 6.9389E-18"
        rpy="0 0 0" />
      <mass
        value="0.19359" />
      <inertia
        ixx="0.00025308"
        ixy="1.5215E-21"
        ixz="2.9081E-21"
        iyy="0.00013682"
        iyz="-1.6941E-20"
        izz="0.00013682" />
    </inertial>
    <visual>
      <origin
        xyz="0 0 0"
        rpy="0 0 0" />
      <geometry>
        <mesh
          filename="package://05149/meshes/RFW.STL" />
      </geometry>
      <material
        name="">
        <color
          rgba="1 1 1 1" />
      </material>
    </visual>
    <collision>
      <origin
        xyz="0 0 0"
        rpy="0 0 0" />
      <geometry>
        <mesh
          filename="package://05149/meshes/RFW.STL" />
      </geometry>
    </collision>
  </link>
  <joint
    name="RFW"
    type="continuous">
    <origin
      xyz="0.0061708 -0.028286 0.058405"
      rpy="-0.70714 0 3.1416" />
    <parent
      link="RFS" />
    <child
      link="RFW" />
    <axis
      xyz="1 0 0" />
    <limit
      effort="3.1"
      velocity="7" />
  </joint>
  <link
    name="LBS">
    <inertial>
      <origin
        xyz="0.075402 -0.020601 0.012626"
        rpy="0 0 0" />
      <mass
        value="0.19701" />
      <inertia
        ixx="1.688E-05"
        ixy="-4.8067E-21"
        ixz="2.2036E-20"
        iyy="5.0218E-05"
        iyz="1.0509E-06"
        izz="4.7245E-05" />
    </inertial>
    <visual>
      <origin
        xyz="0 0 0"
        rpy="0 0 0" />
      <geometry>
        <mesh
          filename="package://05149/meshes/LBS.STL" />
      </geometry>
      <material
        name="">
        <color
          rgba="0.75294 0.75294 0.75294 1" />
      </material>
    </visual>
    <collision>
      <origin
        xyz="0 0 0"
        rpy="0 0 0" />
      <geometry>
        <mesh
          filename="package://05149/meshes/LBS.STL" />
      </geometry>
    </collision>
  </link>
  <joint
    name="LBS"
    type="prismatic">
    <origin
      xyz="0.31516 0.01777 -0.23081"
      rpy="-1.8784 0 3.1416" />
    <parent
      link="Body" />
    <child
      link="LBS" />
    <axis
      xyz="0 0.3028 -0.95305" />
    <limit
      lower="0"
      upper="0"
      effort="0"
      velocity="0" />
  </joint>
  <link
    name="LBC">
    <inertial>
      <origin
        xyz="0.000464526735874993 -0.0408313152633741 0"
        rpy="0 0 0" />
      <mass
        value="0.0433962459602619" />
      <inertia
        ixx="2.11800424724879E-05"
        ixy="5.53822046363831E-07"
        ixz="-1.12496563307212E-22"
        iyy="1.76453344713605E-06"
        iyz="-5.86098823024448E-21"
        izz="2.14947085785555E-05" />
    </inertial>
    <visual>
      <origin
        xyz="0 0 0"
        rpy="0 0 0" />
      <geometry>
        <mesh
          filename="package://05149/meshes/LBC.STL" />
      </geometry>
      <material
        name="">
        <color
          rgba="0.898039215686275 0.917647058823529 0.929411764705882 1" />
      </material>
    </visual>
    <collision>
      <origin
        xyz="0 0 0"
        rpy="0 0 0" />
      <geometry>
        <mesh
          filename="package://05149/meshes/LBC.STL" />
      </geometry>
    </collision>
  </link>
  <joint
    name="LBC"
    type="continuous">
    <origin
      xyz="0.041161 -0.016816 0.00071326"
      rpy="-1.8784 -0.0013926 3.1372" />
    <parent
      link="LBS" />
    <child
      link="LBC" />
    <axis
      xyz="0 1 0" />
  </joint>
  <link
    name="LBW">
    <inertial>
      <origin
        xyz="0.00647305835345524 0 0"
        rpy="0 0 0" />
      <mass
        value="0.0368891747697499" />
      <inertia
        ixx="1.67269024516251E-05"
        ixy="-6.0384184716371E-22"
        ixz="6.31965987990513E-21"
        iyy="8.87926239042531E-06"
        iyz="-3.17637355220363E-22"
        izz="8.87926239042531E-06" />
    </inertial>
    <visual>
      <origin
        xyz="0 0 0"
        rpy="0 0 0" />
      <geometry>
        <mesh
          filename="package://05149/meshes/LBW.STL" />
      </geometry>
      <material
        name="">
        <color
          rgba="1 1 1 1" />
      </material>
    </visual>
    <collision>
      <origin
        xyz="0 0 0"
        rpy="0 0 0" />
      <geometry>
        <mesh
          filename="package://05149/meshes/LBW.STL" />
      </geometry>
    </collision>
  </link>
  <joint
    name="LBW"
    type="continuous">
    <origin
      xyz="0.0095003 -0.068304 0"
      rpy="-2.9662 0 0" />
    <parent
      link="LBC" />
    <child
      link="LBW" />
    <axis
      xyz="1 0 0" />
    <limit
      effort="3.1"
      velocity="7" />
  </joint>
  <link
    name="RBS">
    <inertial>
      <origin
        xyz="0.075402 -0.020601 0.012626"
        rpy="0 0 0" />
      <mass
        value="0.19701" />
      <inertia
        ixx="1.688E-05"
        ixy="1.0289E-20"
        ixz="-2.4348E-20"
        iyy="5.0218E-05"
        iyz="1.0509E-06"
        izz="4.7245E-05" />
    </inertial>
    <visual>
      <origin
        xyz="0 0 0"
        rpy="0 0 0" />
      <geometry>
        <mesh
          filename="package://05149/meshes/RBS.STL" />
      </geometry>
      <material
        name="">
        <color
          rgba="0.75294 0.75294 0.75294 1" />
      </material>
    </visual>
    <collision>
      <origin
        xyz="0 0 0"
        rpy="0 0 0" />
      <geometry>
        <mesh
          filename="package://05149/meshes/RBS.STL" />
      </geometry>
    </collision>
  </link>
  <joint
    name="RBS"
    type="prismatic">
    <origin
      xyz="-0.099161 0.01777 -0.19919"
      rpy="1.2632 0 0" />
    <parent
      link="Body" />
    <child
      link="RBS" />
    <axis
      xyz="0 0.3028 -0.95305" />
    <limit
      lower="0"
      upper="0"
      effort="0"
      velocity="0" />
  </joint>
  <link
    name="RBC">
    <inertial>
      <origin
        xyz="0.000464526735875062 -0.0408313152633741 -5.55111512312578E-17"
        rpy="0 0 0" />
      <mass
        value="0.0433962459602619" />
      <inertia
        ixx="2.1180042472488E-05"
        ixy="5.53822046363839E-07"
        ixz="-2.76211423985068E-22"
        iyy="1.76453344713605E-06"
        iyz="-3.31823183840333E-21"
        izz="2.14947085785555E-05" />
    </inertial>
    <visual>
      <origin
        xyz="0 0 0"
        rpy="0 0 0" />
      <geometry>
        <mesh
          filename="package://05149/meshes/RBC.STL" />
      </geometry>
      <material
        name="">
        <color
          rgba="0.898039215686275 0.917647058823529 0.929411764705882 1" />
      </material>
    </visual>
    <collision>
      <origin
        xyz="0 0 0"
        rpy="0 0 0" />
      <geometry>
        <mesh
          filename="package://05149/meshes/RBC.STL" />
      </geometry>
    </collision>
  </link>
  <joint
    name="RBC"
    type="continuous">
    <origin
      xyz="0.041161 -0.016816 0.00071326"
      rpy="-1.8784 0 3.1416" />
    <parent
      link="RBS" />
    <child
      link="RBC" />
    <axis
      xyz="0 1 0" />
  </joint>
  <link
    name="RBW">
    <inertial>
      <origin
        xyz="0.00647333333471937 -5.55111512312578E-17 -5.55111512312578E-17"
        rpy="0 0 0" />
      <mass
        value="0.0368891747697499" />
      <inertia
        ixx="1.67269024516251E-05"
        ixy="-2.32726892683381E-21"
        ixz="-4.86067499904064E-21"
        iyy="8.8792623904253E-06"
        iyz="-8.470329472543E-22"
        izz="8.8792623904253E-06" />
    </inertial>
    <visual>
      <origin
        xyz="0 0 0"
        rpy="0 0 0" />
      <geometry>
        <mesh
          filename="package://05149/meshes/RBW.STL" />
      </geometry>
      <material
        name="">
        <color
          rgba="1 1 1 1" />
      </material>
    </visual>
    <collision>
      <origin
        xyz="0 0 0"
        rpy="0 0 0" />
      <geometry>
        <mesh
          filename="package://05149/meshes/RBW.STL" />
      </geometry>
    </collision>
  </link>
  <joint
    name="RBW"
    type="continuous">
    <origin
      xyz="0.0095 -0.068304 0"
      rpy="0.99137 0 0" />
    <parent
      link="RBC" />
    <child
      link="RBW" />
    <axis
      xyz="1 0 0" />
    <limit
      effort="3.1"
      velocity="7" />
  </joint>
  <link
    name="front_cam">
    <inertial>
      <origin
        xyz="0.049836 0.061784 0.068723"
        rpy="0 0 0" />
      <mass
        value="0.043612" />
      <inertia
        ixx="4.2948E-06"
        ixy="-8.8579E-10"
        ixz="-1.0181E-09"
        iyy="2.2106E-05"
        iyz="2.1758E-08"
        izz="2.3571E-05" />
    </inertial>
    <visual>
      <origin
        xyz="0 0 0"
        rpy="0 0 0" />
      <geometry>
        <mesh
          filename="package://05149/meshes/front_cam.STL" />
      </geometry>
      <material
        name="">
        <color
          rgba="0.79216 0.81961 0.93333 1" />
      </material>
    </visual>
    <collision>
      <origin
        xyz="0 0 0"
        rpy="0 0 0" />
      <geometry>
        <mesh
          filename="package://05149/meshes/front_cam.STL" />
      </geometry>
    </collision>
  </link>
  <joint
    name="front_cam"
    type="fixed">
    <origin
      xyz="0.058161 0.069504 -0.080278"
      rpy="0 0 0" />
    <parent
      link="Body" />
    <child
      link="front_cam" />
    <axis
      xyz="0 0 0" />
  </joint>
  <link
    name="ball_cam">
    <inertial>
      <origin
        xyz="0.049836 0.061784 -0.0037462"
        rpy="0 0 0" />
      <mass
        value="0.043612" />
      <inertia
        ixx="4.2948E-06"
        ixy="-8.8526E-10"
        ixz="-1.0184E-09"
        iyy="2.2106E-05"
        iyz="2.1758E-08"
        izz="2.3571E-05" />
    </inertial>
    <visual>
      <origin
        xyz="0 0 0"
        rpy="0 0 0" />
      <geometry>
        <mesh
          filename="package://05149/meshes/ball_cam.STL" />
      </geometry>
      <material
        name="">
        <color
          rgba="0.79216 0.81961 0.93333 1" />
      </material>
    </visual>
    <collision>
      <origin
        xyz="0 0 0"
        rpy="0 0 0" />
      <geometry>
        <mesh
          filename="package://05149/meshes/ball_cam.STL" />
      </geometry>
    </collision>
  </link>
  <joint
    name="ball_cam"
    type="fixed">
    <origin
      xyz="0.058165 0.044286 -0.048961"
      rpy="0.63132 0 0" />
    <parent
      link="Body" />
    <child
      link="ball_cam" />
    <axis
      xyz="0 0 0" />
  </joint>
  <link
    name="Lidar">
    <inertial>
      <origin
        xyz="0.10889 0.058557 -0.14231"
        rpy="0 0 0" />
      <mass
        value="5.3249" />
      <inertia
        ixx="0.021938"
        ixy="-4.0175E-06"
        ixz="-1.4798E-06"
        iyy="0.023203"
        iyz="-7.8034E-06"
        izz="0.014905" />
    </inertial>
    <visual>
      <origin
        xyz="0 0 0"
        rpy="0 0 0" />
      <geometry>
        <mesh
          filename="package://05149/meshes/Lidar.STL" />
      </geometry>
      <material
        name="">
        <color
          rgba="0.75294 0.75294 0.75294 1" />
      </material>
    </visual>
    <collision>
      <origin
        xyz="0 0 0"
        rpy="0 0 0" />
      <geometry>
        <mesh
          filename="package://05149/meshes/Lidar.STL" />
      </geometry>
    </collision>
  </link>
  <joint
    name="Lidar"
    type="fixed">
    <origin
      xyz="0.24092 -0.57169 -0.098561"
      rpy="0 -1.5708 0" />
    <parent
      link="Body" />
    <child
      link="Lidar" />
    <axis
      xyz="0 0 0" />
  </joint>
</robot>